INFO - 2022-08-19 14:00:04,699 [cli_supply_curve.py:73] : Running reV supply curve from config file: "/lustre/eaglefs/shared-projects/rev/projects/weto/fy22/bespoke/rev/atb/fy20/eos/01_na_n_mid/debug/config_supply-curve.json"
INFO - 2022-08-19 14:00:04,702 [cli_supply_curve.py:75] : Target output directory: "/lustre/eaglefs/shared-projects/rev/projects/weto/fy22/bespoke/rev/atb/fy20/eos/01_na_n_mid/debug/"
INFO - 2022-08-19 14:00:04,703 [cli_supply_curve.py:76] : Target logging directory: "/lustre/eaglefs/shared-projects/rev/projects/weto/fy22/bespoke/rev/atb/fy20/eos/01_na_n_mid/debug/logs"
INFO - 2022-08-19 14:00:04,719 [cli_supply_curve.py:402] : Running reV Supply Curve on SLURM with node name "debug_supply-curve"
INFO - 2022-08-19 14:00:04,885 [cli_supply_curve.py:420] : Kicked off reV SC job "debug_supply-curve" (SLURM jobid #9921768).
INFO - 2022-08-19 14:00:21,210 [__init__.py:62] : Running with reV version 0.6.5
INFO - 2022-08-19 14:00:21,211 [loggers.py:600] : Running with rex version 0.2.72
INFO - 2022-08-19 14:00:21,211 [supply_curve.py:83] : Supply curve points input: /lustre/eaglefs/shared-projects/rev/projects/weto/fy22/bespoke/rev/atb/fy20/eos/01_na_n_mid/debug/01_na_n_mid_bespoke_node00.h5
INFO - 2022-08-19 14:00:21,211 [supply_curve.py:84] : Transmission table input: /projects/rev/data/transmission/build/connections_128.csv
INFO - 2022-08-19 14:00:37,641 [supply_curve.py:445] : Merging SC table and Trans Table with sc_table_col: trans_table_col mapping: {'sc_row_ind': 'sc_point_row_id', 'sc_col_ind': 'sc_point_col_id'}
INFO - 2022-08-19 14:00:38,624 [supply_curve.py:1032] : Starting full competitive supply curve sort.
ERROR - 2022-08-19 14:00:39,154 [supply_curve.py:367] : The following sc_gid (keys) were connected to substations but were not connected to the respective transmission line gids (values) which is required for full SC sort: {2: [1855], 6: [1790, 1794, 1855], 11: [1925], 29: [1725, 1732], 37: [1790, 1794, 1855], 40: [1752, 1753, 1755], 42: [1633], 77: [1853], 78: [1780, 1823], 137: [1632], 166: [1365, 1626], 174: [1064], 241: [2011], 252: [2372, 2560], 267: [1330, 1793, 1804], 295: [2563, 2565], 327: [2349], 366: [1953, 1965], 370: [1835], 397: [2369], 411: [3595, 3616]}
ERROR - 2022-08-19 14:00:39,154 [cli_supply_curve.py:253] : Supply curve compute failed. Received the following error:
The following sc_gid (keys) were connected to substations but were not connected to the respective transmission line gids (values) which is required for full SC sort: {2: [1855], 6: [1790, 1794, 1855], 11: [1925], 29: [1725, 1732], 37: [1790, 1794, 1855], 40: [1752, 1753, 1755], 42: [1633], 77: [1853], 78: [1780, 1823], 137: [1632], 166: [1365, 1626], 174: [1064], 241: [2011], 252: [2372, 2560], 267: [1330, 1793, 1804], 295: [2563, 2565], 327: [2349], 366: [1953, 1965], 370: [1835], 397: [2369], 411: [3595, 3616]}
Traceback (most recent call last):
  File "/home/twillia2/github/reV/reV/supply_curve/cli_supply_curve.py", line 242, in direct
    out = SupplyCurve.full(sc_points, trans_table,
  File "/home/twillia2/github/reV/reV/supply_curve/supply_curve.py", line 1246, in full
    supply_curve = sc.full_sort(fcr, transmission_costs=transmission_costs,
  File "/home/twillia2/github/reV/reV/supply_curve/supply_curve.py", line 1033, in full_sort
    self._check_substation_conns(self._trans_table)
  File "/home/twillia2/github/reV/reV/supply_curve/supply_curve.py", line 368, in _check_substation_conns
    raise SupplyCurveInputError(msg)
reV.utilities.exceptions.SupplyCurveInputError: The following sc_gid (keys) were connected to substations but were not connected to the respective transmission line gids (values) which is required for full SC sort: {2: [1855], 6: [1790, 1794, 1855], 11: [1925], 29: [1725, 1732], 37: [1790, 1794, 1855], 40: [1752, 1753, 1755], 42: [1633], 77: [1853], 78: [1780, 1823], 137: [1632], 166: [1365, 1626], 174: [1064], 241: [2011], 252: [2372, 2560], 267: [1330, 1793, 1804], 295: [2563, 2565], 327: [2349], 366: [1953, 1965], 370: [1835], 397: [2369], 411: [3595, 3616]}
ERROR - 2022-08-19 14:00:39,158 [cli_supply_curve.py:427] : Error running reV Supply Curve CLI.
Traceback (most recent call last):
  File "/home/twillia2/github/reV/reV/supply_curve/cli_supply_curve.py", line 425, in <module>
    main(obj={})
  File "/shared-projects/rev/modulefiles/alternate_envs/devruns/lib/python3.8/site-packages/click/core.py", line 1130, in __call__
    return self.main(*args, **kwargs)
  File "/shared-projects/rev/modulefiles/alternate_envs/devruns/lib/python3.8/site-packages/click/core.py", line 1055, in main
    rv = self.invoke(ctx)
  File "/shared-projects/rev/modulefiles/alternate_envs/devruns/lib/python3.8/site-packages/click/core.py", line 1657, in invoke
    return _process_result(sub_ctx.command.invoke(sub_ctx))
  File "/shared-projects/rev/modulefiles/alternate_envs/devruns/lib/python3.8/site-packages/click/core.py", line 1635, in invoke
    rv = super().invoke(ctx)
  File "/shared-projects/rev/modulefiles/alternate_envs/devruns/lib/python3.8/site-packages/click/core.py", line 1404, in invoke
    return ctx.invoke(self.callback, **ctx.params)
  File "/shared-projects/rev/modulefiles/alternate_envs/devruns/lib/python3.8/site-packages/click/core.py", line 760, in invoke
    return __callback(*args, **kwargs)
  File "/shared-projects/rev/modulefiles/alternate_envs/devruns/lib/python3.8/site-packages/click/decorators.py", line 26, in new_func
    return f(get_current_context(), *args, **kwargs)
  File "/home/twillia2/github/reV/reV/supply_curve/cli_supply_curve.py", line 255, in direct
    raise e
  File "/home/twillia2/github/reV/reV/supply_curve/cli_supply_curve.py", line 242, in direct
    out = SupplyCurve.full(sc_points, trans_table,
  File "/home/twillia2/github/reV/reV/supply_curve/supply_curve.py", line 1246, in full
    supply_curve = sc.full_sort(fcr, transmission_costs=transmission_costs,
  File "/home/twillia2/github/reV/reV/supply_curve/supply_curve.py", line 1033, in full_sort
    self._check_substation_conns(self._trans_table)
  File "/home/twillia2/github/reV/reV/supply_curve/supply_curve.py", line 368, in _check_substation_conns
    raise SupplyCurveInputError(msg)
reV.utilities.exceptions.SupplyCurveInputError: The following sc_gid (keys) were connected to substations but were not connected to the respective transmission line gids (values) which is required for full SC sort: {2: [1855], 6: [1790, 1794, 1855], 11: [1925], 29: [1725, 1732], 37: [1790, 1794, 1855], 40: [1752, 1753, 1755], 42: [1633], 77: [1853], 78: [1780, 1823], 137: [1632], 166: [1365, 1626], 174: [1064], 241: [2011], 252: [2372, 2560], 267: [1330, 1793, 1804], 295: [2563, 2565], 327: [2349], 366: [1953, 1965], 370: [1835], 397: [2369], 411: [3595, 3616]}
INFO - 2022-08-19 15:50:14,926 [cli_supply_curve.py:73] : Running reV supply curve from config file: "/lustre/eaglefs/shared-projects/rev/projects/weto/fy22/bespoke/rev/atb/fy20/eos/01_na_n_mid/debug/config_supply-curve.json"
INFO - 2022-08-19 15:50:14,943 [cli_supply_curve.py:75] : Target output directory: "/lustre/eaglefs/shared-projects/rev/projects/weto/fy22/bespoke/rev/atb/fy20/eos/01_na_n_mid/debug/"
INFO - 2022-08-19 15:50:14,943 [cli_supply_curve.py:76] : Target logging directory: "/lustre/eaglefs/shared-projects/rev/projects/weto/fy22/bespoke/rev/atb/fy20/eos/01_na_n_mid/debug/logs"
INFO - 2022-08-19 15:50:16,017 [cli_supply_curve.py:402] : Running reV Supply Curve on SLURM with node name "debug_supply-curve"
INFO - 2022-08-19 15:50:16,112 [cli_supply_curve.py:420] : Kicked off reV SC job "debug_supply-curve" (SLURM jobid #9921891).
INFO - 2022-08-19 15:50:30,444 [__init__.py:62] : Running with reV version 0.6.5
INFO - 2022-08-19 15:50:30,467 [loggers.py:600] : Running with rex version 0.2.72
INFO - 2022-08-19 15:50:30,467 [supply_curve.py:83] : Supply curve points input: /lustre/eaglefs/shared-projects/rev/projects/weto/fy22/bespoke/rev/atb/fy20/eos/01_na_n_mid/debug/01_na_n_mid_bespoke_node00.h5
INFO - 2022-08-19 15:50:30,467 [supply_curve.py:84] : Transmission table input: /projects/rev/data/transmission/build/connections_128.csv
INFO - 2022-08-19 15:50:47,594 [supply_curve.py:445] : Merging SC table and Trans Table with sc_table_col: trans_table_col mapping: {'sc_row_ind': 'sc_point_row_id', 'sc_col_ind': 'sc_point_col_id'}
INFO - 2022-08-19 15:50:48,576 [supply_curve.py:1032] : Starting full competitive supply curve sort.
ERROR - 2022-08-19 15:50:49,110 [supply_curve.py:367] : The following sc_gid (keys) were connected to substations but were not connected to the respective transmission line gids (values) which is required for full SC sort: {2: [1855], 6: [1790, 1794, 1855], 11: [1925], 29: [1725, 1732], 37: [1790, 1794, 1855], 40: [1752, 1753, 1755], 42: [1633], 77: [1853], 78: [1780, 1823], 137: [1632], 166: [1365, 1626], 174: [1064], 241: [2011], 252: [2372, 2560], 267: [1330, 1793, 1804], 295: [2563, 2565], 327: [2349], 366: [1953, 1965], 370: [1835], 397: [2369], 411: [3595, 3616]}
ERROR - 2022-08-19 15:50:49,110 [cli_supply_curve.py:253] : Supply curve compute failed. Received the following error:
The following sc_gid (keys) were connected to substations but were not connected to the respective transmission line gids (values) which is required for full SC sort: {2: [1855], 6: [1790, 1794, 1855], 11: [1925], 29: [1725, 1732], 37: [1790, 1794, 1855], 40: [1752, 1753, 1755], 42: [1633], 77: [1853], 78: [1780, 1823], 137: [1632], 166: [1365, 1626], 174: [1064], 241: [2011], 252: [2372, 2560], 267: [1330, 1793, 1804], 295: [2563, 2565], 327: [2349], 366: [1953, 1965], 370: [1835], 397: [2369], 411: [3595, 3616]}
Traceback (most recent call last):
  File "/home/twillia2/github/reV/reV/supply_curve/cli_supply_curve.py", line 242, in direct
    out = SupplyCurve.full(sc_points, trans_table,
  File "/home/twillia2/github/reV/reV/supply_curve/supply_curve.py", line 1246, in full
    supply_curve = sc.full_sort(fcr, transmission_costs=transmission_costs,
  File "/home/twillia2/github/reV/reV/supply_curve/supply_curve.py", line 1033, in full_sort
    self._check_substation_conns(self._trans_table)
  File "/home/twillia2/github/reV/reV/supply_curve/supply_curve.py", line 368, in _check_substation_conns
    raise SupplyCurveInputError(msg)
reV.utilities.exceptions.SupplyCurveInputError: The following sc_gid (keys) were connected to substations but were not connected to the respective transmission line gids (values) which is required for full SC sort: {2: [1855], 6: [1790, 1794, 1855], 11: [1925], 29: [1725, 1732], 37: [1790, 1794, 1855], 40: [1752, 1753, 1755], 42: [1633], 77: [1853], 78: [1780, 1823], 137: [1632], 166: [1365, 1626], 174: [1064], 241: [2011], 252: [2372, 2560], 267: [1330, 1793, 1804], 295: [2563, 2565], 327: [2349], 366: [1953, 1965], 370: [1835], 397: [2369], 411: [3595, 3616]}
ERROR - 2022-08-19 15:50:49,114 [cli_supply_curve.py:427] : Error running reV Supply Curve CLI.
Traceback (most recent call last):
  File "/home/twillia2/github/reV/reV/supply_curve/cli_supply_curve.py", line 425, in <module>
    main(obj={})
  File "/shared-projects/rev/modulefiles/alternate_envs/devruns/lib/python3.8/site-packages/click/core.py", line 1130, in __call__
    return self.main(*args, **kwargs)
  File "/shared-projects/rev/modulefiles/alternate_envs/devruns/lib/python3.8/site-packages/click/core.py", line 1055, in main
    rv = self.invoke(ctx)
  File "/shared-projects/rev/modulefiles/alternate_envs/devruns/lib/python3.8/site-packages/click/core.py", line 1657, in invoke
    return _process_result(sub_ctx.command.invoke(sub_ctx))
  File "/shared-projects/rev/modulefiles/alternate_envs/devruns/lib/python3.8/site-packages/click/core.py", line 1635, in invoke
    rv = super().invoke(ctx)
  File "/shared-projects/rev/modulefiles/alternate_envs/devruns/lib/python3.8/site-packages/click/core.py", line 1404, in invoke
    return ctx.invoke(self.callback, **ctx.params)
  File "/shared-projects/rev/modulefiles/alternate_envs/devruns/lib/python3.8/site-packages/click/core.py", line 760, in invoke
    return __callback(*args, **kwargs)
  File "/shared-projects/rev/modulefiles/alternate_envs/devruns/lib/python3.8/site-packages/click/decorators.py", line 26, in new_func
    return f(get_current_context(), *args, **kwargs)
  File "/home/twillia2/github/reV/reV/supply_curve/cli_supply_curve.py", line 255, in direct
    raise e
  File "/home/twillia2/github/reV/reV/supply_curve/cli_supply_curve.py", line 242, in direct
    out = SupplyCurve.full(sc_points, trans_table,
  File "/home/twillia2/github/reV/reV/supply_curve/supply_curve.py", line 1246, in full
    supply_curve = sc.full_sort(fcr, transmission_costs=transmission_costs,
  File "/home/twillia2/github/reV/reV/supply_curve/supply_curve.py", line 1033, in full_sort
    self._check_substation_conns(self._trans_table)
  File "/home/twillia2/github/reV/reV/supply_curve/supply_curve.py", line 368, in _check_substation_conns
    raise SupplyCurveInputError(msg)
reV.utilities.exceptions.SupplyCurveInputError: The following sc_gid (keys) were connected to substations but were not connected to the respective transmission line gids (values) which is required for full SC sort: {2: [1855], 6: [1790, 1794, 1855], 11: [1925], 29: [1725, 1732], 37: [1790, 1794, 1855], 40: [1752, 1753, 1755], 42: [1633], 77: [1853], 78: [1780, 1823], 137: [1632], 166: [1365, 1626], 174: [1064], 241: [2011], 252: [2372, 2560], 267: [1330, 1793, 1804], 295: [2563, 2565], 327: [2349], 366: [1953, 1965], 370: [1835], 397: [2369], 411: [3595, 3616]}
INFO - 2022-08-22 09:27:15,667 [cli_supply_curve.py:73] : Running reV supply curve from config file: "/lustre/eaglefs/shared-projects/rev/projects/weto/fy22/bespoke/rev/atb/fy20/eos/01_na_n_mid/debug/config_supply-curve.json"
INFO - 2022-08-22 09:27:15,691 [cli_supply_curve.py:75] : Target output directory: "/lustre/eaglefs/shared-projects/rev/projects/weto/fy22/bespoke/rev/atb/fy20/eos/01_na_n_mid/debug/"
INFO - 2022-08-22 09:27:15,691 [cli_supply_curve.py:76] : Target logging directory: "/lustre/eaglefs/shared-projects/rev/projects/weto/fy22/bespoke/rev/atb/fy20/eos/01_na_n_mid/debug/logs"
INFO - 2022-08-22 09:27:16,015 [cli_supply_curve.py:402] : Running reV Supply Curve on SLURM with node name "debug_supply-curve"
INFO - 2022-08-22 09:27:16,993 [cli_supply_curve.py:420] : Kicked off reV SC job "debug_supply-curve" (SLURM jobid #9928798).
INFO - 2022-08-22 09:27:28,557 [__init__.py:62] : Running with reV version 0.6.5
INFO - 2022-08-22 09:27:28,557 [loggers.py:600] : Running with rex version 0.2.72
INFO - 2022-08-22 09:27:28,557 [supply_curve.py:83] : Supply curve points input: /lustre/eaglefs/shared-projects/rev/projects/weto/fy22/bespoke/rev/atb/fy20/eos/01_na_n_mid/debug/01_na_n_mid_bespoke_node00.h5
INFO - 2022-08-22 09:27:28,557 [supply_curve.py:84] : Transmission table input: /projects/rev/data/transmission/build/connections_128.csv
INFO - 2022-08-22 09:27:45,546 [supply_curve.py:445] : Merging SC table and Trans Table with sc_table_col: trans_table_col mapping: {'sc_row_ind': 'sc_point_row_id', 'sc_col_ind': 'sc_point_col_id'}
INFO - 2022-08-22 09:27:46,533 [supply_curve.py:1032] : Starting full competitive supply curve sort.
ERROR - 2022-08-22 09:27:47,069 [supply_curve.py:367] : The following sc_gid (keys) were connected to substations but were not connected to the respective transmission line gids (values) which is required for full SC sort: {2: [1855], 6: [1790, 1794, 1855], 11: [1925], 29: [1725, 1732], 37: [1790, 1794, 1855], 40: [1752, 1753, 1755], 42: [1633], 77: [1853], 78: [1780, 1823], 137: [1632], 166: [1365, 1626], 174: [1064], 241: [2011], 252: [2372, 2560], 267: [1330, 1793, 1804], 295: [2563, 2565], 327: [2349], 366: [1953, 1965], 370: [1835], 397: [2369], 411: [3595, 3616]}
ERROR - 2022-08-22 09:27:47,069 [cli_supply_curve.py:253] : Supply curve compute failed. Received the following error:
The following sc_gid (keys) were connected to substations but were not connected to the respective transmission line gids (values) which is required for full SC sort: {2: [1855], 6: [1790, 1794, 1855], 11: [1925], 29: [1725, 1732], 37: [1790, 1794, 1855], 40: [1752, 1753, 1755], 42: [1633], 77: [1853], 78: [1780, 1823], 137: [1632], 166: [1365, 1626], 174: [1064], 241: [2011], 252: [2372, 2560], 267: [1330, 1793, 1804], 295: [2563, 2565], 327: [2349], 366: [1953, 1965], 370: [1835], 397: [2369], 411: [3595, 3616]}
Traceback (most recent call last):
  File "/home/twillia2/github/reV/reV/supply_curve/cli_supply_curve.py", line 242, in direct
    out = SupplyCurve.full(sc_points, trans_table,
  File "/home/twillia2/github/reV/reV/supply_curve/supply_curve.py", line 1246, in full
    supply_curve = sc.full_sort(fcr, transmission_costs=transmission_costs,
  File "/home/twillia2/github/reV/reV/supply_curve/supply_curve.py", line 1033, in full_sort
    self._check_substation_conns(self._trans_table)
  File "/home/twillia2/github/reV/reV/supply_curve/supply_curve.py", line 368, in _check_substation_conns
    raise SupplyCurveInputError(msg)
reV.utilities.exceptions.SupplyCurveInputError: The following sc_gid (keys) were connected to substations but were not connected to the respective transmission line gids (values) which is required for full SC sort: {2: [1855], 6: [1790, 1794, 1855], 11: [1925], 29: [1725, 1732], 37: [1790, 1794, 1855], 40: [1752, 1753, 1755], 42: [1633], 77: [1853], 78: [1780, 1823], 137: [1632], 166: [1365, 1626], 174: [1064], 241: [2011], 252: [2372, 2560], 267: [1330, 1793, 1804], 295: [2563, 2565], 327: [2349], 366: [1953, 1965], 370: [1835], 397: [2369], 411: [3595, 3616]}
ERROR - 2022-08-22 09:27:47,073 [cli_supply_curve.py:427] : Error running reV Supply Curve CLI.
Traceback (most recent call last):
  File "/home/twillia2/github/reV/reV/supply_curve/cli_supply_curve.py", line 425, in <module>
    main(obj={})
  File "/shared-projects/rev/modulefiles/alternate_envs/devruns/lib/python3.8/site-packages/click/core.py", line 1130, in __call__
    return self.main(*args, **kwargs)
  File "/shared-projects/rev/modulefiles/alternate_envs/devruns/lib/python3.8/site-packages/click/core.py", line 1055, in main
    rv = self.invoke(ctx)
  File "/shared-projects/rev/modulefiles/alternate_envs/devruns/lib/python3.8/site-packages/click/core.py", line 1657, in invoke
    return _process_result(sub_ctx.command.invoke(sub_ctx))
  File "/shared-projects/rev/modulefiles/alternate_envs/devruns/lib/python3.8/site-packages/click/core.py", line 1635, in invoke
    rv = super().invoke(ctx)
  File "/shared-projects/rev/modulefiles/alternate_envs/devruns/lib/python3.8/site-packages/click/core.py", line 1404, in invoke
    return ctx.invoke(self.callback, **ctx.params)
  File "/shared-projects/rev/modulefiles/alternate_envs/devruns/lib/python3.8/site-packages/click/core.py", line 760, in invoke
    return __callback(*args, **kwargs)
  File "/shared-projects/rev/modulefiles/alternate_envs/devruns/lib/python3.8/site-packages/click/decorators.py", line 26, in new_func
    return f(get_current_context(), *args, **kwargs)
  File "/home/twillia2/github/reV/reV/supply_curve/cli_supply_curve.py", line 255, in direct
    raise e
  File "/home/twillia2/github/reV/reV/supply_curve/cli_supply_curve.py", line 242, in direct
    out = SupplyCurve.full(sc_points, trans_table,
  File "/home/twillia2/github/reV/reV/supply_curve/supply_curve.py", line 1246, in full
    supply_curve = sc.full_sort(fcr, transmission_costs=transmission_costs,
  File "/home/twillia2/github/reV/reV/supply_curve/supply_curve.py", line 1033, in full_sort
    self._check_substation_conns(self._trans_table)
  File "/home/twillia2/github/reV/reV/supply_curve/supply_curve.py", line 368, in _check_substation_conns
    raise SupplyCurveInputError(msg)
reV.utilities.exceptions.SupplyCurveInputError: The following sc_gid (keys) were connected to substations but were not connected to the respective transmission line gids (values) which is required for full SC sort: {2: [1855], 6: [1790, 1794, 1855], 11: [1925], 29: [1725, 1732], 37: [1790, 1794, 1855], 40: [1752, 1753, 1755], 42: [1633], 77: [1853], 78: [1780, 1823], 137: [1632], 166: [1365, 1626], 174: [1064], 241: [2011], 252: [2372, 2560], 267: [1330, 1793, 1804], 295: [2563, 2565], 327: [2349], 366: [1953, 1965], 370: [1835], 397: [2369], 411: [3595, 3616]}
INFO - 2022-08-22 10:46:16,338 [cli_supply_curve.py:73] : Running reV supply curve from config file: "/shared-projects/rev/projects/weto/fy22/bespoke/rev/atb/fy20/eos/01_na_n_mid/debug/config_supply-curve.json"
INFO - 2022-08-22 10:46:16,353 [cli_supply_curve.py:75] : Target output directory: "/shared-projects/rev/projects/weto/fy22/bespoke/rev/atb/fy20/eos/01_na_n_mid/debug/"
INFO - 2022-08-22 10:46:16,353 [cli_supply_curve.py:76] : Target logging directory: "/lustre/eaglefs/shared-projects/rev/projects/weto/fy22/bespoke/rev/atb/fy20/eos/01_na_n_mid/debug/logs"
INFO - 2022-08-22 10:46:17,187 [cli_supply_curve.py:402] : Running reV Supply Curve on SLURM with node name "debug_supply-curve"
INFO - 2022-08-22 10:46:17,280 [cli_supply_curve.py:420] : Kicked off reV SC job "debug_supply-curve" (SLURM jobid #9928865).
INFO - 2022-08-22 10:46:28,956 [__init__.py:62] : Running with reV version 0.6.5
INFO - 2022-08-22 10:46:28,957 [loggers.py:600] : Running with rex version 0.2.72
INFO - 2022-08-22 10:46:28,957 [supply_curve.py:83] : Supply curve points input: /lustre/eaglefs/shared-projects/rev/projects/weto/fy22/bespoke/rev/atb/fy20/eos/01_na_n_mid/debug/01_na_n_mid_bespoke_node00.h5
INFO - 2022-08-22 10:46:28,957 [supply_curve.py:84] : Transmission table input: /projects/rev/data/transmission/build/connections_128.csv
INFO - 2022-08-22 10:46:45,730 [supply_curve.py:445] : Merging SC table and Trans Table with sc_table_col: trans_table_col mapping: {'sc_row_ind': 'sc_point_row_id', 'sc_col_ind': 'sc_point_col_id'}
INFO - 2022-08-22 10:46:46,714 [supply_curve.py:1032] : Starting full competitive supply curve sort.
ERROR - 2022-08-22 10:46:47,303 [supply_curve.py:367] : The following sc_gid (keys) were connected to substations but were not connected to the respective transmission line gids (values) which is required for full SC sort: {2: [1855], 6: [1790, 1794, 1855], 11: [1925], 29: [1725, 1732], 37: [1790, 1794, 1855], 40: [1752, 1753, 1755], 42: [1633], 77: [1853], 78: [1780, 1823], 137: [1632], 166: [1365, 1626], 174: [1064], 241: [2011], 252: [2372, 2560], 267: [1330, 1793, 1804], 295: [2563, 2565], 327: [2349], 366: [1953, 1965], 370: [1835], 397: [2369], 411: [3595, 3616]}
ERROR - 2022-08-22 10:46:47,303 [cli_supply_curve.py:253] : Supply curve compute failed. Received the following error:
The following sc_gid (keys) were connected to substations but were not connected to the respective transmission line gids (values) which is required for full SC sort: {2: [1855], 6: [1790, 1794, 1855], 11: [1925], 29: [1725, 1732], 37: [1790, 1794, 1855], 40: [1752, 1753, 1755], 42: [1633], 77: [1853], 78: [1780, 1823], 137: [1632], 166: [1365, 1626], 174: [1064], 241: [2011], 252: [2372, 2560], 267: [1330, 1793, 1804], 295: [2563, 2565], 327: [2349], 366: [1953, 1965], 370: [1835], 397: [2369], 411: [3595, 3616]}
Traceback (most recent call last):
  File "/home/twillia2/github/reV/reV/supply_curve/cli_supply_curve.py", line 242, in direct
    out = SupplyCurve.full(sc_points, trans_table,
  File "/home/twillia2/github/reV/reV/supply_curve/supply_curve.py", line 1246, in full
    supply_curve = sc.full_sort(fcr, transmission_costs=transmission_costs,
  File "/home/twillia2/github/reV/reV/supply_curve/supply_curve.py", line 1033, in full_sort
    self._check_substation_conns(self._trans_table)
  File "/home/twillia2/github/reV/reV/supply_curve/supply_curve.py", line 368, in _check_substation_conns
    raise SupplyCurveInputError(msg)
reV.utilities.exceptions.SupplyCurveInputError: The following sc_gid (keys) were connected to substations but were not connected to the respective transmission line gids (values) which is required for full SC sort: {2: [1855], 6: [1790, 1794, 1855], 11: [1925], 29: [1725, 1732], 37: [1790, 1794, 1855], 40: [1752, 1753, 1755], 42: [1633], 77: [1853], 78: [1780, 1823], 137: [1632], 166: [1365, 1626], 174: [1064], 241: [2011], 252: [2372, 2560], 267: [1330, 1793, 1804], 295: [2563, 2565], 327: [2349], 366: [1953, 1965], 370: [1835], 397: [2369], 411: [3595, 3616]}
ERROR - 2022-08-22 10:46:47,308 [cli_supply_curve.py:427] : Error running reV Supply Curve CLI.
Traceback (most recent call last):
  File "/home/twillia2/github/reV/reV/supply_curve/cli_supply_curve.py", line 425, in <module>
    main(obj={})
  File "/shared-projects/rev/modulefiles/alternate_envs/devruns/lib/python3.8/site-packages/click/core.py", line 1130, in __call__
    return self.main(*args, **kwargs)
  File "/shared-projects/rev/modulefiles/alternate_envs/devruns/lib/python3.8/site-packages/click/core.py", line 1055, in main
    rv = self.invoke(ctx)
  File "/shared-projects/rev/modulefiles/alternate_envs/devruns/lib/python3.8/site-packages/click/core.py", line 1657, in invoke
    return _process_result(sub_ctx.command.invoke(sub_ctx))
  File "/shared-projects/rev/modulefiles/alternate_envs/devruns/lib/python3.8/site-packages/click/core.py", line 1635, in invoke
    rv = super().invoke(ctx)
  File "/shared-projects/rev/modulefiles/alternate_envs/devruns/lib/python3.8/site-packages/click/core.py", line 1404, in invoke
    return ctx.invoke(self.callback, **ctx.params)
  File "/shared-projects/rev/modulefiles/alternate_envs/devruns/lib/python3.8/site-packages/click/core.py", line 760, in invoke
    return __callback(*args, **kwargs)
  File "/shared-projects/rev/modulefiles/alternate_envs/devruns/lib/python3.8/site-packages/click/decorators.py", line 26, in new_func
    return f(get_current_context(), *args, **kwargs)
  File "/home/twillia2/github/reV/reV/supply_curve/cli_supply_curve.py", line 255, in direct
    raise e
  File "/home/twillia2/github/reV/reV/supply_curve/cli_supply_curve.py", line 242, in direct
    out = SupplyCurve.full(sc_points, trans_table,
  File "/home/twillia2/github/reV/reV/supply_curve/supply_curve.py", line 1246, in full
    supply_curve = sc.full_sort(fcr, transmission_costs=transmission_costs,
  File "/home/twillia2/github/reV/reV/supply_curve/supply_curve.py", line 1033, in full_sort
    self._check_substation_conns(self._trans_table)
  File "/home/twillia2/github/reV/reV/supply_curve/supply_curve.py", line 368, in _check_substation_conns
    raise SupplyCurveInputError(msg)
reV.utilities.exceptions.SupplyCurveInputError: The following sc_gid (keys) were connected to substations but were not connected to the respective transmission line gids (values) which is required for full SC sort: {2: [1855], 6: [1790, 1794, 1855], 11: [1925], 29: [1725, 1732], 37: [1790, 1794, 1855], 40: [1752, 1753, 1755], 42: [1633], 77: [1853], 78: [1780, 1823], 137: [1632], 166: [1365, 1626], 174: [1064], 241: [2011], 252: [2372, 2560], 267: [1330, 1793, 1804], 295: [2563, 2565], 327: [2349], 366: [1953, 1965], 370: [1835], 397: [2369], 411: [3595, 3616]}
INFO - 2022-08-22 10:48:46,767 [cli_supply_curve.py:73] : Running reV supply curve from config file: "/shared-projects/rev/projects/weto/fy22/bespoke/rev/atb/fy20/eos/01_na_n_mid/debug/config_supply-curve.json"
INFO - 2022-08-22 10:48:46,768 [cli_supply_curve.py:75] : Target output directory: "/shared-projects/rev/projects/weto/fy22/bespoke/rev/atb/fy20/eos/01_na_n_mid/debug/"
INFO - 2022-08-22 10:48:46,768 [cli_supply_curve.py:76] : Target logging directory: "/lustre/eaglefs/shared-projects/rev/projects/weto/fy22/bespoke/rev/atb/fy20/eos/01_na_n_mid/debug/logs"
INFO - 2022-08-22 10:48:47,485 [cli_supply_curve.py:402] : Running reV Supply Curve on SLURM with node name "debug_supply-curve"
INFO - 2022-08-22 10:48:47,542 [cli_supply_curve.py:420] : Kicked off reV SC job "debug_supply-curve" (SLURM jobid #9928869).
INFO - 2022-08-22 10:48:59,043 [__init__.py:62] : Running with reV version 0.6.5
INFO - 2022-08-22 10:48:59,043 [loggers.py:600] : Running with rex version 0.2.72
INFO - 2022-08-22 10:48:59,043 [supply_curve.py:83] : Supply curve points input: /lustre/eaglefs/shared-projects/rev/projects/weto/fy22/bespoke/rev/atb/fy20/eos/01_na_n_mid/debug/01_na_n_mid_bespoke_node00.h5
INFO - 2022-08-22 10:48:59,043 [supply_curve.py:84] : Transmission table input: /projects/rev/data/transmission/build/connections_128.csv
INFO - 2022-08-22 10:49:15,492 [supply_curve.py:445] : Merging SC table and Trans Table with sc_table_col: trans_table_col mapping: {'sc_row_ind': 'sc_point_row_id', 'sc_col_ind': 'sc_point_col_id'}
INFO - 2022-08-22 10:49:16,480 [supply_curve.py:1032] : Starting full competitive supply curve sort.
ERROR - 2022-08-22 10:49:17,009 [supply_curve.py:367] : The following sc_gid (keys) were connected to substations but were not connected to the respective transmission line gids (values) which is required for full SC sort: {2: [1855], 6: [1790, 1794, 1855], 11: [1925], 29: [1725, 1732], 37: [1790, 1794, 1855], 40: [1752, 1753, 1755], 42: [1633], 77: [1853], 78: [1780, 1823], 137: [1632], 166: [1365, 1626], 174: [1064], 241: [2011], 252: [2372, 2560], 267: [1330, 1793, 1804], 295: [2563, 2565], 327: [2349], 366: [1953, 1965], 370: [1835], 397: [2369], 411: [3595, 3616]}
ERROR - 2022-08-22 10:49:17,010 [cli_supply_curve.py:253] : Supply curve compute failed. Received the following error:
The following sc_gid (keys) were connected to substations but were not connected to the respective transmission line gids (values) which is required for full SC sort: {2: [1855], 6: [1790, 1794, 1855], 11: [1925], 29: [1725, 1732], 37: [1790, 1794, 1855], 40: [1752, 1753, 1755], 42: [1633], 77: [1853], 78: [1780, 1823], 137: [1632], 166: [1365, 1626], 174: [1064], 241: [2011], 252: [2372, 2560], 267: [1330, 1793, 1804], 295: [2563, 2565], 327: [2349], 366: [1953, 1965], 370: [1835], 397: [2369], 411: [3595, 3616]}
Traceback (most recent call last):
  File "/home/twillia2/github/reV/reV/supply_curve/cli_supply_curve.py", line 242, in direct
    out = SupplyCurve.full(sc_points, trans_table,
  File "/home/twillia2/github/reV/reV/supply_curve/supply_curve.py", line 1246, in full
    supply_curve = sc.full_sort(fcr, transmission_costs=transmission_costs,
  File "/home/twillia2/github/reV/reV/supply_curve/supply_curve.py", line 1033, in full_sort
    self._check_substation_conns(self._trans_table)
  File "/home/twillia2/github/reV/reV/supply_curve/supply_curve.py", line 368, in _check_substation_conns
    raise SupplyCurveInputError(msg)
reV.utilities.exceptions.SupplyCurveInputError: The following sc_gid (keys) were connected to substations but were not connected to the respective transmission line gids (values) which is required for full SC sort: {2: [1855], 6: [1790, 1794, 1855], 11: [1925], 29: [1725, 1732], 37: [1790, 1794, 1855], 40: [1752, 1753, 1755], 42: [1633], 77: [1853], 78: [1780, 1823], 137: [1632], 166: [1365, 1626], 174: [1064], 241: [2011], 252: [2372, 2560], 267: [1330, 1793, 1804], 295: [2563, 2565], 327: [2349], 366: [1953, 1965], 370: [1835], 397: [2369], 411: [3595, 3616]}
ERROR - 2022-08-22 10:49:17,012 [cli_supply_curve.py:427] : Error running reV Supply Curve CLI.
Traceback (most recent call last):
  File "/home/twillia2/github/reV/reV/supply_curve/cli_supply_curve.py", line 425, in <module>
    main(obj={})
  File "/shared-projects/rev/modulefiles/alternate_envs/devruns/lib/python3.8/site-packages/click/core.py", line 1130, in __call__
    return self.main(*args, **kwargs)
  File "/shared-projects/rev/modulefiles/alternate_envs/devruns/lib/python3.8/site-packages/click/core.py", line 1055, in main
    rv = self.invoke(ctx)
  File "/shared-projects/rev/modulefiles/alternate_envs/devruns/lib/python3.8/site-packages/click/core.py", line 1657, in invoke
    return _process_result(sub_ctx.command.invoke(sub_ctx))
  File "/shared-projects/rev/modulefiles/alternate_envs/devruns/lib/python3.8/site-packages/click/core.py", line 1635, in invoke
    rv = super().invoke(ctx)
  File "/shared-projects/rev/modulefiles/alternate_envs/devruns/lib/python3.8/site-packages/click/core.py", line 1404, in invoke
    return ctx.invoke(self.callback, **ctx.params)
  File "/shared-projects/rev/modulefiles/alternate_envs/devruns/lib/python3.8/site-packages/click/core.py", line 760, in invoke
    return __callback(*args, **kwargs)
  File "/shared-projects/rev/modulefiles/alternate_envs/devruns/lib/python3.8/site-packages/click/decorators.py", line 26, in new_func
    return f(get_current_context(), *args, **kwargs)
  File "/home/twillia2/github/reV/reV/supply_curve/cli_supply_curve.py", line 255, in direct
    raise e
  File "/home/twillia2/github/reV/reV/supply_curve/cli_supply_curve.py", line 242, in direct
    out = SupplyCurve.full(sc_points, trans_table,
  File "/home/twillia2/github/reV/reV/supply_curve/supply_curve.py", line 1246, in full
    supply_curve = sc.full_sort(fcr, transmission_costs=transmission_costs,
  File "/home/twillia2/github/reV/reV/supply_curve/supply_curve.py", line 1033, in full_sort
    self._check_substation_conns(self._trans_table)
  File "/home/twillia2/github/reV/reV/supply_curve/supply_curve.py", line 368, in _check_substation_conns
    raise SupplyCurveInputError(msg)
reV.utilities.exceptions.SupplyCurveInputError: The following sc_gid (keys) were connected to substations but were not connected to the respective transmission line gids (values) which is required for full SC sort: {2: [1855], 6: [1790, 1794, 1855], 11: [1925], 29: [1725, 1732], 37: [1790, 1794, 1855], 40: [1752, 1753, 1755], 42: [1633], 77: [1853], 78: [1780, 1823], 137: [1632], 166: [1365, 1626], 174: [1064], 241: [2011], 252: [2372, 2560], 267: [1330, 1793, 1804], 295: [2563, 2565], 327: [2349], 366: [1953, 1965], 370: [1835], 397: [2369], 411: [3595, 3616]}
INFO - 2022-08-22 11:48:49,690 [cli_supply_curve.py:73] : Running reV supply curve from config file: "/shared-projects/rev/projects/weto/fy22/bespoke/rev/atb/fy20/eos/01_na_n_mid/debug/config_supply-curve.json"
INFO - 2022-08-22 11:48:49,721 [cli_supply_curve.py:75] : Target output directory: "/shared-projects/rev/projects/weto/fy22/bespoke/rev/atb/fy20/eos/01_na_n_mid/debug/"
INFO - 2022-08-22 11:48:49,721 [cli_supply_curve.py:76] : Target logging directory: "/lustre/eaglefs/shared-projects/rev/projects/weto/fy22/bespoke/rev/atb/fy20/eos/01_na_n_mid/debug/logs"
INFO - 2022-08-22 11:48:50,003 [cli_supply_curve.py:402] : Running reV Supply Curve on SLURM with node name "debug_supply-curve"
INFO - 2022-08-22 11:48:50,081 [cli_supply_curve.py:420] : Kicked off reV SC job "debug_supply-curve" (SLURM jobid #9928962).
INFO - 2022-08-22 11:49:21,264 [__init__.py:62] : Running with reV version 0.6.5
INFO - 2022-08-22 11:49:21,283 [loggers.py:600] : Running with rex version 0.2.72
INFO - 2022-08-22 11:49:21,283 [supply_curve.py:83] : Supply curve points input: /lustre/eaglefs/shared-projects/rev/projects/weto/fy22/bespoke/rev/atb/fy20/eos/01_na_n_mid/debug/01_na_n_mid_bespoke_node00.h5
INFO - 2022-08-22 11:49:21,283 [supply_curve.py:84] : Transmission table input: /projects/rev/data/transmission/build/connections_128.csv
INFO - 2022-08-22 11:49:40,621 [supply_curve.py:445] : Merging SC table and Trans Table with sc_table_col: trans_table_col mapping: {'sc_row_ind': 'sc_point_row_id', 'sc_col_ind': 'sc_point_col_id'}
INFO - 2022-08-22 11:49:41,715 [supply_curve.py:1032] : Starting full competitive supply curve sort.
ERROR - 2022-08-22 11:49:42,270 [supply_curve.py:367] : The following sc_gid (keys) were connected to substations but were not connected to the respective transmission line gids (values) which is required for full SC sort: {2: [1855], 6: [1790, 1794, 1855], 11: [1925], 29: [1725, 1732], 37: [1790, 1794, 1855], 40: [1752, 1753, 1755], 42: [1633], 77: [1853], 78: [1780, 1823], 137: [1632], 166: [1365, 1626], 174: [1064], 241: [2011], 252: [2372, 2560], 267: [1330, 1793, 1804], 295: [2563, 2565], 327: [2349], 366: [1953, 1965], 370: [1835], 397: [2369], 411: [3595, 3616]}
ERROR - 2022-08-22 11:49:42,270 [cli_supply_curve.py:253] : Supply curve compute failed. Received the following error:
The following sc_gid (keys) were connected to substations but were not connected to the respective transmission line gids (values) which is required for full SC sort: {2: [1855], 6: [1790, 1794, 1855], 11: [1925], 29: [1725, 1732], 37: [1790, 1794, 1855], 40: [1752, 1753, 1755], 42: [1633], 77: [1853], 78: [1780, 1823], 137: [1632], 166: [1365, 1626], 174: [1064], 241: [2011], 252: [2372, 2560], 267: [1330, 1793, 1804], 295: [2563, 2565], 327: [2349], 366: [1953, 1965], 370: [1835], 397: [2369], 411: [3595, 3616]}
Traceback (most recent call last):
  File "/home/twillia2/github/reV/reV/supply_curve/cli_supply_curve.py", line 242, in direct
    out = SupplyCurve.full(sc_points, trans_table,
  File "/home/twillia2/github/reV/reV/supply_curve/supply_curve.py", line 1246, in full
    supply_curve = sc.full_sort(fcr, transmission_costs=transmission_costs,
  File "/home/twillia2/github/reV/reV/supply_curve/supply_curve.py", line 1033, in full_sort
    self._check_substation_conns(self._trans_table)
  File "/home/twillia2/github/reV/reV/supply_curve/supply_curve.py", line 368, in _check_substation_conns
    raise SupplyCurveInputError(msg)
reV.utilities.exceptions.SupplyCurveInputError: The following sc_gid (keys) were connected to substations but were not connected to the respective transmission line gids (values) which is required for full SC sort: {2: [1855], 6: [1790, 1794, 1855], 11: [1925], 29: [1725, 1732], 37: [1790, 1794, 1855], 40: [1752, 1753, 1755], 42: [1633], 77: [1853], 78: [1780, 1823], 137: [1632], 166: [1365, 1626], 174: [1064], 241: [2011], 252: [2372, 2560], 267: [1330, 1793, 1804], 295: [2563, 2565], 327: [2349], 366: [1953, 1965], 370: [1835], 397: [2369], 411: [3595, 3616]}
ERROR - 2022-08-22 11:49:42,276 [cli_supply_curve.py:427] : Error running reV Supply Curve CLI.
Traceback (most recent call last):
  File "/home/twillia2/github/reV/reV/supply_curve/cli_supply_curve.py", line 425, in <module>
    main(obj={})
  File "/shared-projects/rev/modulefiles/alternate_envs/devruns/lib/python3.8/site-packages/click/core.py", line 1130, in __call__
    return self.main(*args, **kwargs)
  File "/shared-projects/rev/modulefiles/alternate_envs/devruns/lib/python3.8/site-packages/click/core.py", line 1055, in main
    rv = self.invoke(ctx)
  File "/shared-projects/rev/modulefiles/alternate_envs/devruns/lib/python3.8/site-packages/click/core.py", line 1657, in invoke
    return _process_result(sub_ctx.command.invoke(sub_ctx))
  File "/shared-projects/rev/modulefiles/alternate_envs/devruns/lib/python3.8/site-packages/click/core.py", line 1635, in invoke
    rv = super().invoke(ctx)
  File "/shared-projects/rev/modulefiles/alternate_envs/devruns/lib/python3.8/site-packages/click/core.py", line 1404, in invoke
    return ctx.invoke(self.callback, **ctx.params)
  File "/shared-projects/rev/modulefiles/alternate_envs/devruns/lib/python3.8/site-packages/click/core.py", line 760, in invoke
    return __callback(*args, **kwargs)
  File "/shared-projects/rev/modulefiles/alternate_envs/devruns/lib/python3.8/site-packages/click/decorators.py", line 26, in new_func
    return f(get_current_context(), *args, **kwargs)
  File "/home/twillia2/github/reV/reV/supply_curve/cli_supply_curve.py", line 255, in direct
    raise e
  File "/home/twillia2/github/reV/reV/supply_curve/cli_supply_curve.py", line 242, in direct
    out = SupplyCurve.full(sc_points, trans_table,
  File "/home/twillia2/github/reV/reV/supply_curve/supply_curve.py", line 1246, in full
    supply_curve = sc.full_sort(fcr, transmission_costs=transmission_costs,
  File "/home/twillia2/github/reV/reV/supply_curve/supply_curve.py", line 1033, in full_sort
    self._check_substation_conns(self._trans_table)
  File "/home/twillia2/github/reV/reV/supply_curve/supply_curve.py", line 368, in _check_substation_conns
    raise SupplyCurveInputError(msg)
reV.utilities.exceptions.SupplyCurveInputError: The following sc_gid (keys) were connected to substations but were not connected to the respective transmission line gids (values) which is required for full SC sort: {2: [1855], 6: [1790, 1794, 1855], 11: [1925], 29: [1725, 1732], 37: [1790, 1794, 1855], 40: [1752, 1753, 1755], 42: [1633], 77: [1853], 78: [1780, 1823], 137: [1632], 166: [1365, 1626], 174: [1064], 241: [2011], 252: [2372, 2560], 267: [1330, 1793, 1804], 295: [2563, 2565], 327: [2349], 366: [1953, 1965], 370: [1835], 397: [2369], 411: [3595, 3616]}
INFO - 2022-08-22 11:54:08,726 [cli_supply_curve.py:73] : Running reV supply curve from config file: "/shared-projects/rev/projects/weto/fy22/bespoke/rev/atb/fy20/eos/01_na_n_mid/debug/config_supply-curve.json"
INFO - 2022-08-22 11:54:08,726 [cli_supply_curve.py:75] : Target output directory: "/shared-projects/rev/projects/weto/fy22/bespoke/rev/atb/fy20/eos/01_na_n_mid/debug/"
INFO - 2022-08-22 11:54:08,726 [cli_supply_curve.py:76] : Target logging directory: "/lustre/eaglefs/shared-projects/rev/projects/weto/fy22/bespoke/rev/atb/fy20/eos/01_na_n_mid/debug/logs"
ERROR - 2022-08-22 11:54:08,727 [base_config.py:153] : allocation is not a valid config entry for BaseExecutionConfig! Must be one of:
['config_dir', 'config_keys', 'log_level', 'max_workers', 'memory_utilization_limit', 'name', 'nodes', 'option', 'sh_script', 'sites_per_worker']
INFO - 2022-08-22 11:55:08,414 [cli_supply_curve.py:73] : Running reV supply curve from config file: "/shared-projects/rev/projects/weto/fy22/bespoke/rev/atb/fy20/eos/01_na_n_mid/debug/config_supply-curve.json"
INFO - 2022-08-22 11:55:08,414 [cli_supply_curve.py:75] : Target output directory: "/shared-projects/rev/projects/weto/fy22/bespoke/rev/atb/fy20/eos/01_na_n_mid/debug/"
INFO - 2022-08-22 11:55:08,414 [cli_supply_curve.py:76] : Target logging directory: "/lustre/eaglefs/shared-projects/rev/projects/weto/fy22/bespoke/rev/atb/fy20/eos/01_na_n_mid/debug/logs"
ERROR - 2022-08-22 11:55:08,415 [base_config.py:153] : memory is not a valid config entry for BaseExecutionConfig! Must be one of:
['config_dir', 'config_keys', 'log_level', 'max_workers', 'memory_utilization_limit', 'name', 'nodes', 'option', 'sh_script', 'sites_per_worker']
INFO - 2022-08-22 11:55:24,712 [cli_supply_curve.py:73] : Running reV supply curve from config file: "/shared-projects/rev/projects/weto/fy22/bespoke/rev/atb/fy20/eos/01_na_n_mid/debug/config_supply-curve.json"
INFO - 2022-08-22 11:55:24,712 [cli_supply_curve.py:75] : Target output directory: "/shared-projects/rev/projects/weto/fy22/bespoke/rev/atb/fy20/eos/01_na_n_mid/debug/"
INFO - 2022-08-22 11:55:24,712 [cli_supply_curve.py:76] : Target logging directory: "/lustre/eaglefs/shared-projects/rev/projects/weto/fy22/bespoke/rev/atb/fy20/eos/01_na_n_mid/debug/logs"
INFO - 2022-08-22 11:55:25,746 [__init__.py:62] : Running with reV version 0.6.5
INFO - 2022-08-22 11:55:25,747 [loggers.py:600] : Running with rex version 0.2.72
INFO - 2022-08-22 11:55:25,747 [supply_curve.py:83] : Supply curve points input: /lustre/eaglefs/shared-projects/rev/projects/weto/fy22/bespoke/rev/atb/fy20/eos/01_na_n_mid/debug/01_na_n_mid_bespoke_node00.h5
INFO - 2022-08-22 11:55:25,747 [supply_curve.py:84] : Transmission table input: /projects/rev/data/transmission/build/connections_128.csv
ERROR - 2022-08-22 11:55:28,256 [cli_supply_curve.py:253] : Supply curve compute failed. Received the following error:
Error tokenizing data. C error: Calling read(nbytes) on source failed. Try engine='python'.
Traceback (most recent call last):
  File "/home/twillia2/github/reV/reV/supply_curve/cli_supply_curve.py", line 242, in direct
    out = SupplyCurve.full(sc_points, trans_table,
  File "/home/twillia2/github/reV/reV/supply_curve/supply_curve.py", line 1245, in full
    sc = cls(sc_points, trans_table, sc_features=sc_features)
  File "/home/twillia2/github/reV/reV/supply_curve/supply_curve.py", line 88, in __init__
    self._trans_table = self._map_tables(self._sc_points, trans_table)
  File "/home/twillia2/github/reV/reV/supply_curve/supply_curve.py", line 495, in _map_tables
    trans_sc_table = cls._merge_sc_trans_tables(sc_points, trans_table,
  File "/home/twillia2/github/reV/reV/supply_curve/supply_curve.py", line 441, in _merge_sc_trans_tables
    trans_table = cls._parse_trans_table(trans_table)
  File "/home/twillia2/github/reV/reV/supply_curve/supply_curve.py", line 209, in _parse_trans_table
    trans_table = parse_table(trans_table)
  File "/home/twillia2/github/rex/rex/utilities/utilities.py", line 442, in parse_table
    table = pd.read_csv(table)
  File "/lustre/eaglefs/shared-projects/rev/modulefiles/alternate_envs/devruns/lib/python3.8/site-packages/pandas/util/_decorators.py", line 311, in wrapper
    return func(*args, **kwargs)
  File "/lustre/eaglefs/shared-projects/rev/modulefiles/alternate_envs/devruns/lib/python3.8/site-packages/pandas/io/parsers/readers.py", line 680, in read_csv
    return _read(filepath_or_buffer, kwds)
  File "/lustre/eaglefs/shared-projects/rev/modulefiles/alternate_envs/devruns/lib/python3.8/site-packages/pandas/io/parsers/readers.py", line 581, in _read
    return parser.read(nrows)
  File "/lustre/eaglefs/shared-projects/rev/modulefiles/alternate_envs/devruns/lib/python3.8/site-packages/pandas/io/parsers/readers.py", line 1255, in read
    index, columns, col_dict = self._engine.read(nrows)
  File "/lustre/eaglefs/shared-projects/rev/modulefiles/alternate_envs/devruns/lib/python3.8/site-packages/pandas/io/parsers/c_parser_wrapper.py", line 225, in read
    chunks = self._reader.read_low_memory(nrows)
  File "pandas/_libs/parsers.pyx", line 805, in pandas._libs.parsers.TextReader.read_low_memory
  File "pandas/_libs/parsers.pyx", line 861, in pandas._libs.parsers.TextReader._read_rows
  File "pandas/_libs/parsers.pyx", line 847, in pandas._libs.parsers.TextReader._tokenize_rows
  File "pandas/_libs/parsers.pyx", line 1960, in pandas._libs.parsers.raise_parser_error
pandas.errors.ParserError: Error tokenizing data. C error: Calling read(nbytes) on source failed. Try engine='python'.
INFO - 2022-08-22 11:55:33,402 [cli_supply_curve.py:73] : Running reV supply curve from config file: "/shared-projects/rev/projects/weto/fy22/bespoke/rev/atb/fy20/eos/01_na_n_mid/debug/config_supply-curve.json"
INFO - 2022-08-22 11:55:33,402 [cli_supply_curve.py:75] : Target output directory: "/shared-projects/rev/projects/weto/fy22/bespoke/rev/atb/fy20/eos/01_na_n_mid/debug/"
INFO - 2022-08-22 11:55:33,402 [cli_supply_curve.py:76] : Target logging directory: "/lustre/eaglefs/shared-projects/rev/projects/weto/fy22/bespoke/rev/atb/fy20/eos/01_na_n_mid/debug/logs"
INFO - 2022-08-22 11:55:33,409 [__init__.py:62] : Running with reV version 0.6.5
INFO - 2022-08-22 11:55:33,409 [loggers.py:600] : Running with rex version 0.2.72
INFO - 2022-08-22 11:55:33,409 [supply_curve.py:83] : Supply curve points input: /lustre/eaglefs/shared-projects/rev/projects/weto/fy22/bespoke/rev/atb/fy20/eos/01_na_n_mid/debug/01_na_n_mid_bespoke_node00.h5
INFO - 2022-08-22 11:55:33,409 [supply_curve.py:84] : Transmission table input: /projects/rev/data/transmission/build/connections_128.csv
INFO - 2022-08-22 11:56:04,705 [supply_curve.py:445] : Merging SC table and Trans Table with sc_table_col: trans_table_col mapping: {'sc_row_ind': 'sc_point_row_id', 'sc_col_ind': 'sc_point_col_id'}
INFO - 2022-08-22 11:56:06,852 [supply_curve.py:1032] : Starting full competitive supply curve sort.
ERROR - 2022-08-22 11:56:07,616 [supply_curve.py:367] : The following sc_gid (keys) were connected to substations but were not connected to the respective transmission line gids (values) which is required for full SC sort: {2: [1855], 6: [1790, 1794, 1855], 11: [1925], 29: [1725, 1732], 37: [1790, 1794, 1855], 40: [1752, 1753, 1755], 42: [1633], 77: [1853], 78: [1780, 1823], 137: [1632], 166: [1365, 1626], 174: [1064], 241: [2011], 252: [2372, 2560], 267: [1330, 1793, 1804], 295: [2563, 2565], 327: [2349], 366: [1953, 1965], 370: [1835], 397: [2369], 411: [3595, 3616]}
ERROR - 2022-08-22 11:56:07,617 [cli_supply_curve.py:253] : Supply curve compute failed. Received the following error:
The following sc_gid (keys) were connected to substations but were not connected to the respective transmission line gids (values) which is required for full SC sort: {2: [1855], 6: [1790, 1794, 1855], 11: [1925], 29: [1725, 1732], 37: [1790, 1794, 1855], 40: [1752, 1753, 1755], 42: [1633], 77: [1853], 78: [1780, 1823], 137: [1632], 166: [1365, 1626], 174: [1064], 241: [2011], 252: [2372, 2560], 267: [1330, 1793, 1804], 295: [2563, 2565], 327: [2349], 366: [1953, 1965], 370: [1835], 397: [2369], 411: [3595, 3616]}
Traceback (most recent call last):
  File "/home/twillia2/github/reV/reV/supply_curve/cli_supply_curve.py", line 242, in direct
    out = SupplyCurve.full(sc_points, trans_table,
  File "/home/twillia2/github/reV/reV/supply_curve/supply_curve.py", line 1246, in full
    supply_curve = sc.full_sort(fcr, transmission_costs=transmission_costs,
  File "/home/twillia2/github/reV/reV/supply_curve/supply_curve.py", line 1033, in full_sort
    self._check_substation_conns(self._trans_table)
  File "/home/twillia2/github/reV/reV/supply_curve/supply_curve.py", line 368, in _check_substation_conns
    raise SupplyCurveInputError(msg)
reV.utilities.exceptions.SupplyCurveInputError: The following sc_gid (keys) were connected to substations but were not connected to the respective transmission line gids (values) which is required for full SC sort: {2: [1855], 6: [1790, 1794, 1855], 11: [1925], 29: [1725, 1732], 37: [1790, 1794, 1855], 40: [1752, 1753, 1755], 42: [1633], 77: [1853], 78: [1780, 1823], 137: [1632], 166: [1365, 1626], 174: [1064], 241: [2011], 252: [2372, 2560], 267: [1330, 1793, 1804], 295: [2563, 2565], 327: [2349], 366: [1953, 1965], 370: [1835], 397: [2369], 411: [3595, 3616]}
INFO - 2022-08-22 11:57:12,766 [cli_supply_curve.py:73] : Running reV supply curve from config file: "/shared-projects/rev/projects/weto/fy22/bespoke/rev/atb/fy20/eos/01_na_n_mid/debug/config_supply-curve.json"
INFO - 2022-08-22 11:57:12,767 [cli_supply_curve.py:75] : Target output directory: "/shared-projects/rev/projects/weto/fy22/bespoke/rev/atb/fy20/eos/01_na_n_mid/debug/"
INFO - 2022-08-22 11:57:12,767 [cli_supply_curve.py:76] : Target logging directory: "/lustre/eaglefs/shared-projects/rev/projects/weto/fy22/bespoke/rev/atb/fy20/eos/01_na_n_mid/debug/logs"
INFO - 2022-08-22 11:57:12,778 [__init__.py:62] : Running with reV version 0.6.5
INFO - 2022-08-22 11:57:12,778 [loggers.py:600] : Running with rex version 0.2.72
INFO - 2022-08-22 11:57:12,779 [supply_curve.py:83] : Supply curve points input: /lustre/eaglefs/shared-projects/rev/projects/weto/fy22/bespoke/rev/atb/fy20/eos/01_na_n_mid/debug/01_na_n_mid_bespoke_node00.h5
INFO - 2022-08-22 11:57:12,779 [supply_curve.py:84] : Transmission table input: /projects/rev/data/transmission/build/connections_128.csv
INFO - 2022-08-22 11:57:31,827 [cli_supply_curve.py:73] : Running reV supply curve from config file: "/shared-projects/rev/projects/weto/fy22/bespoke/rev/atb/fy20/eos/01_na_n_mid/debug/config_supply-curve.json"
INFO - 2022-08-22 11:57:31,827 [cli_supply_curve.py:75] : Target output directory: "/shared-projects/rev/projects/weto/fy22/bespoke/rev/atb/fy20/eos/01_na_n_mid/debug/"
INFO - 2022-08-22 11:57:31,828 [cli_supply_curve.py:76] : Target logging directory: "/lustre/eaglefs/shared-projects/rev/projects/weto/fy22/bespoke/rev/atb/fy20/eos/01_na_n_mid/debug/logs"
INFO - 2022-08-22 11:57:31,839 [__init__.py:62] : Running with reV version 0.6.5
INFO - 2022-08-22 11:57:31,839 [loggers.py:600] : Running with rex version 0.2.72
INFO - 2022-08-22 11:57:31,839 [supply_curve.py:83] : Supply curve points input: /lustre/eaglefs/shared-projects/rev/projects/weto/fy22/bespoke/rev/atb/fy20/eos/01_na_n_mid/debug/01_na_n_mid_bespoke_node00.h5
INFO - 2022-08-22 11:57:31,839 [supply_curve.py:84] : Transmission table input: /projects/rev/data/transmission/build/connections_128.csv
INFO - 2022-08-22 11:58:02,280 [supply_curve.py:445] : Merging SC table and Trans Table with sc_table_col: trans_table_col mapping: {'sc_row_ind': 'sc_point_row_id', 'sc_col_ind': 'sc_point_col_id'}
INFO - 2022-08-22 11:58:04,387 [supply_curve.py:1032] : Starting full competitive supply curve sort.
INFO - 2022-08-22 12:03:40,267 [cli_supply_curve.py:73] : Running reV supply curve from config file: "/lustre/eaglefs/shared-projects/rev/projects/weto/fy22/bespoke/rev/atb/fy20/eos/01_na_n_mid/debug/config_supply-curve.json"
INFO - 2022-08-22 12:03:40,269 [cli_supply_curve.py:75] : Target output directory: "/lustre/eaglefs/shared-projects/rev/projects/weto/fy22/bespoke/rev/atb/fy20/eos/01_na_n_mid/debug/"
INFO - 2022-08-22 12:03:40,270 [cli_supply_curve.py:76] : Target logging directory: "/lustre/eaglefs/shared-projects/rev/projects/weto/fy22/bespoke/rev/atb/fy20/eos/01_na_n_mid/debug/logs"
INFO - 2022-08-22 12:03:40,283 [__init__.py:62] : Running with reV version 0.6.5
INFO - 2022-08-22 12:03:40,283 [loggers.py:600] : Running with rex version 0.2.72
INFO - 2022-08-22 12:03:40,284 [supply_curve.py:83] : Supply curve points input: /lustre/eaglefs/shared-projects/rev/projects/weto/fy22/bespoke/rev/atb/fy20/eos/01_na_n_mid/debug/01_na_n_mid_bespoke_node00.h5
INFO - 2022-08-22 12:03:40,284 [supply_curve.py:84] : Transmission table input: /projects/rev/data/transmission/build/connections_128.csv
INFO - 2022-08-22 12:04:12,244 [supply_curve.py:445] : Merging SC table and Trans Table with sc_table_col: trans_table_col mapping: {'sc_row_ind': 'sc_point_row_id', 'sc_col_ind': 'sc_point_col_id'}
INFO - 2022-08-22 12:04:14,345 [supply_curve.py:1032] : Starting full competitive supply curve sort.
INFO - 2022-08-22 16:21:46,690 [cli_supply_curve.py:73] : Running reV supply curve from config file: "/lustre/eaglefs/shared-projects/rev/projects/weto/fy22/bespoke/rev/atb/fy20/eos/01_na_n_mid/debug/config_supply-curve.json"
INFO - 2022-08-22 16:21:46,706 [cli_supply_curve.py:75] : Target output directory: "/lustre/eaglefs/shared-projects/rev/projects/weto/fy22/bespoke/rev/atb/fy20/eos/01_na_n_mid/debug/"
INFO - 2022-08-22 16:21:46,706 [cli_supply_curve.py:76] : Target logging directory: "/lustre/eaglefs/shared-projects/rev/projects/weto/fy22/bespoke/rev/atb/fy20/eos/01_na_n_mid/debug/logs"
INFO - 2022-08-22 16:21:46,713 [__init__.py:62] : Running with reV version 0.6.5
INFO - 2022-08-22 16:21:46,713 [loggers.py:600] : Running with rex version 0.2.72
INFO - 2022-08-22 16:21:46,713 [supply_curve.py:83] : Supply curve points input: /lustre/eaglefs/shared-projects/rev/projects/weto/fy22/bespoke/rev/atb/fy20/eos/01_na_n_mid/debug/01_na_n_mid_bespoke_node00.h5
INFO - 2022-08-22 16:21:46,713 [supply_curve.py:84] : Transmission table input: /projects/rev/data/transmission/build/connections_128.csv
INFO - 2022-08-22 16:22:18,880 [supply_curve.py:445] : Merging SC table and Trans Table with sc_table_col: trans_table_col mapping: {'sc_row_ind': 'sc_point_row_id', 'sc_col_ind': 'sc_point_col_id'}
INFO - 2022-08-22 16:22:20,960 [supply_curve.py:1032] : Starting full competitive supply curve sort.
ERROR - 2022-08-22 16:22:21,723 [supply_curve.py:367] : The following sc_gid (keys) were connected to substations but were not connected to the respective transmission line gids (values) which is required for full SC sort: {2: [1855], 6: [1790, 1794, 1855], 11: [1925], 29: [1725, 1732], 37: [1790, 1794, 1855], 40: [1752, 1753, 1755], 42: [1633], 77: [1853], 78: [1780, 1823], 137: [1632], 166: [1365, 1626], 174: [1064], 241: [2011], 252: [2372, 2560], 267: [1330, 1793, 1804], 295: [2563, 2565], 327: [2349], 366: [1953, 1965], 370: [1835], 397: [2369], 411: [3595, 3616]}
ERROR - 2022-08-22 16:22:21,723 [cli_supply_curve.py:253] : Supply curve compute failed. Received the following error:
The following sc_gid (keys) were connected to substations but were not connected to the respective transmission line gids (values) which is required for full SC sort: {2: [1855], 6: [1790, 1794, 1855], 11: [1925], 29: [1725, 1732], 37: [1790, 1794, 1855], 40: [1752, 1753, 1755], 42: [1633], 77: [1853], 78: [1780, 1823], 137: [1632], 166: [1365, 1626], 174: [1064], 241: [2011], 252: [2372, 2560], 267: [1330, 1793, 1804], 295: [2563, 2565], 327: [2349], 366: [1953, 1965], 370: [1835], 397: [2369], 411: [3595, 3616]}
Traceback (most recent call last):
  File "/home/twillia2/github/reV/reV/supply_curve/cli_supply_curve.py", line 242, in direct
    out = SupplyCurve.full(sc_points, trans_table,
  File "/home/twillia2/github/reV/reV/supply_curve/supply_curve.py", line 1246, in full
    supply_curve = sc.full_sort(fcr, transmission_costs=transmission_costs,
  File "/home/twillia2/github/reV/reV/supply_curve/supply_curve.py", line 1033, in full_sort
    self._check_substation_conns(self._trans_table)
  File "/home/twillia2/github/reV/reV/supply_curve/supply_curve.py", line 368, in _check_substation_conns
    raise SupplyCurveInputError(msg)
reV.utilities.exceptions.SupplyCurveInputError: The following sc_gid (keys) were connected to substations but were not connected to the respective transmission line gids (values) which is required for full SC sort: {2: [1855], 6: [1790, 1794, 1855], 11: [1925], 29: [1725, 1732], 37: [1790, 1794, 1855], 40: [1752, 1753, 1755], 42: [1633], 77: [1853], 78: [1780, 1823], 137: [1632], 166: [1365, 1626], 174: [1064], 241: [2011], 252: [2372, 2560], 267: [1330, 1793, 1804], 295: [2563, 2565], 327: [2349], 366: [1953, 1965], 370: [1835], 397: [2369], 411: [3595, 3616]}
INFO - 2022-08-23 08:17:17,273 [cli_supply_curve.py:73] : Running reV supply curve from config file: "/lustre/eaglefs/shared-projects/rev/projects/weto/fy22/bespoke/rev/atb/fy20/eos/01_na_n_mid/debug/config_supply-curve.json"
INFO - 2022-08-23 08:17:17,319 [cli_supply_curve.py:75] : Target output directory: "/lustre/eaglefs/shared-projects/rev/projects/weto/fy22/bespoke/rev/atb/fy20/eos/01_na_n_mid/debug/"
INFO - 2022-08-23 08:17:17,320 [cli_supply_curve.py:76] : Target logging directory: "/lustre/eaglefs/shared-projects/rev/projects/weto/fy22/bespoke/rev/atb/fy20/eos/01_na_n_mid/debug/logs"
INFO - 2022-08-23 08:17:17,328 [__init__.py:62] : Running with reV version 0.6.5
INFO - 2022-08-23 08:17:17,328 [loggers.py:600] : Running with rex version 0.2.72
INFO - 2022-08-23 08:17:17,328 [supply_curve.py:83] : Supply curve points input: /lustre/eaglefs/shared-projects/rev/projects/weto/fy22/bespoke/rev/atb/fy20/eos/01_na_n_mid/debug/01_na_n_mid_bespoke_node00.h5
INFO - 2022-08-23 08:17:17,328 [supply_curve.py:84] : Transmission table input: /projects/rev/data/transmission/build/connections_128.csv
INFO - 2022-08-23 08:17:49,662 [supply_curve.py:445] : Merging SC table and Trans Table with sc_table_col: trans_table_col mapping: {'sc_row_ind': 'sc_point_row_id', 'sc_col_ind': 'sc_point_col_id'}
INFO - 2022-08-23 08:17:51,764 [supply_curve.py:1032] : Starting full competitive supply curve sort.
ERROR - 2022-08-23 08:17:52,497 [supply_curve.py:367] : The following sc_gid (keys) were connected to substations but were not connected to the respective transmission line gids (values) which is required for full SC sort: {2: [1855], 6: [1790, 1794, 1855], 11: [1925], 29: [1725, 1732], 37: [1790, 1794, 1855], 40: [1752, 1753, 1755], 42: [1633], 77: [1853], 78: [1780, 1823], 137: [1632], 166: [1365, 1626], 174: [1064], 241: [2011], 252: [2372, 2560], 267: [1330, 1793, 1804], 295: [2563, 2565], 327: [2349], 366: [1953, 1965], 370: [1835], 397: [2369], 411: [3595, 3616]}
ERROR - 2022-08-23 08:17:52,497 [cli_supply_curve.py:253] : Supply curve compute failed. Received the following error:
The following sc_gid (keys) were connected to substations but were not connected to the respective transmission line gids (values) which is required for full SC sort: {2: [1855], 6: [1790, 1794, 1855], 11: [1925], 29: [1725, 1732], 37: [1790, 1794, 1855], 40: [1752, 1753, 1755], 42: [1633], 77: [1853], 78: [1780, 1823], 137: [1632], 166: [1365, 1626], 174: [1064], 241: [2011], 252: [2372, 2560], 267: [1330, 1793, 1804], 295: [2563, 2565], 327: [2349], 366: [1953, 1965], 370: [1835], 397: [2369], 411: [3595, 3616]}
Traceback (most recent call last):
  File "/home/twillia2/github/reV/reV/supply_curve/cli_supply_curve.py", line 242, in direct
    out = SupplyCurve.full(sc_points, trans_table,
  File "/home/twillia2/github/reV/reV/supply_curve/supply_curve.py", line 1246, in full
    supply_curve = sc.full_sort(fcr, transmission_costs=transmission_costs,
  File "/home/twillia2/github/reV/reV/supply_curve/supply_curve.py", line 1033, in full_sort
    self._check_substation_conns(self._trans_table)
  File "/home/twillia2/github/reV/reV/supply_curve/supply_curve.py", line 368, in _check_substation_conns
    raise SupplyCurveInputError(msg)
reV.utilities.exceptions.SupplyCurveInputError: The following sc_gid (keys) were connected to substations but were not connected to the respective transmission line gids (values) which is required for full SC sort: {2: [1855], 6: [1790, 1794, 1855], 11: [1925], 29: [1725, 1732], 37: [1790, 1794, 1855], 40: [1752, 1753, 1755], 42: [1633], 77: [1853], 78: [1780, 1823], 137: [1632], 166: [1365, 1626], 174: [1064], 241: [2011], 252: [2372, 2560], 267: [1330, 1793, 1804], 295: [2563, 2565], 327: [2349], 366: [1953, 1965], 370: [1835], 397: [2369], 411: [3595, 3616]}
INFO - 2022-08-23 09:18:59,510 [cli_supply_curve.py:73] : Running reV supply curve from config file: "/lustre/eaglefs/shared-projects/rev/projects/weto/fy22/bespoke/rev/atb/fy20/eos/01_na_n_mid/debug/config_supply-curve.json"
INFO - 2022-08-23 09:18:59,510 [cli_supply_curve.py:75] : Target output directory: "/lustre/eaglefs/shared-projects/rev/projects/weto/fy22/bespoke/rev/atb/fy20/eos/01_na_n_mid/debug/"
INFO - 2022-08-23 09:18:59,511 [cli_supply_curve.py:76] : Target logging directory: "/lustre/eaglefs/shared-projects/rev/projects/weto/fy22/bespoke/rev/atb/fy20/eos/01_na_n_mid/debug/logs"
INFO - 2022-08-23 09:18:59,518 [__init__.py:62] : Running with reV version 0.6.5
INFO - 2022-08-23 09:18:59,518 [loggers.py:600] : Running with rex version 0.2.72
INFO - 2022-08-23 09:18:59,518 [supply_curve.py:83] : Supply curve points input: /lustre/eaglefs/shared-projects/rev/projects/weto/fy22/bespoke/rev/atb/fy20/eos/01_na_n_mid/debug/01_na_n_mid_bespoke_node00.h5
INFO - 2022-08-23 09:18:59,518 [supply_curve.py:84] : Transmission table input: /projects/rev/data/transmission/build/connections_128.csv
INFO - 2022-08-23 09:19:31,113 [supply_curve.py:445] : Merging SC table and Trans Table with sc_table_col: trans_table_col mapping: {'sc_row_ind': 'sc_point_row_id', 'sc_col_ind': 'sc_point_col_id'}
INFO - 2022-08-23 09:19:33,221 [supply_curve.py:1032] : Starting full competitive supply curve sort.
ERROR - 2022-08-23 09:19:33,964 [supply_curve.py:367] : The following sc_gid (keys) were connected to substations but were not connected to the respective transmission line gids (values) which is required for full SC sort: {2: [1855], 6: [1790, 1794, 1855], 11: [1925], 29: [1725, 1732], 37: [1790, 1794, 1855], 40: [1752, 1753, 1755], 42: [1633], 77: [1853], 78: [1780, 1823], 137: [1632], 166: [1365, 1626], 174: [1064], 241: [2011], 252: [2372, 2560], 267: [1330, 1793, 1804], 295: [2563, 2565], 327: [2349], 366: [1953, 1965], 370: [1835], 397: [2369], 411: [3595, 3616]}
ERROR - 2022-08-23 09:19:33,964 [cli_supply_curve.py:253] : Supply curve compute failed. Received the following error:
The following sc_gid (keys) were connected to substations but were not connected to the respective transmission line gids (values) which is required for full SC sort: {2: [1855], 6: [1790, 1794, 1855], 11: [1925], 29: [1725, 1732], 37: [1790, 1794, 1855], 40: [1752, 1753, 1755], 42: [1633], 77: [1853], 78: [1780, 1823], 137: [1632], 166: [1365, 1626], 174: [1064], 241: [2011], 252: [2372, 2560], 267: [1330, 1793, 1804], 295: [2563, 2565], 327: [2349], 366: [1953, 1965], 370: [1835], 397: [2369], 411: [3595, 3616]}
Traceback (most recent call last):
  File "/home/twillia2/github/reV/reV/supply_curve/cli_supply_curve.py", line 242, in direct
    out = SupplyCurve.full(sc_points, trans_table,
  File "/home/twillia2/github/reV/reV/supply_curve/supply_curve.py", line 1246, in full
    supply_curve = sc.full_sort(fcr, transmission_costs=transmission_costs,
  File "/home/twillia2/github/reV/reV/supply_curve/supply_curve.py", line 1033, in full_sort
    self._check_substation_conns(self._trans_table)
  File "/home/twillia2/github/reV/reV/supply_curve/supply_curve.py", line 368, in _check_substation_conns
    raise SupplyCurveInputError(msg)
reV.utilities.exceptions.SupplyCurveInputError: The following sc_gid (keys) were connected to substations but were not connected to the respective transmission line gids (values) which is required for full SC sort: {2: [1855], 6: [1790, 1794, 1855], 11: [1925], 29: [1725, 1732], 37: [1790, 1794, 1855], 40: [1752, 1753, 1755], 42: [1633], 77: [1853], 78: [1780, 1823], 137: [1632], 166: [1365, 1626], 174: [1064], 241: [2011], 252: [2372, 2560], 267: [1330, 1793, 1804], 295: [2563, 2565], 327: [2349], 366: [1953, 1965], 370: [1835], 397: [2369], 411: [3595, 3616]}
